[34m[1mwandb[0m: [33mWARNING[0m Config item 'loss_fn' was locked by 'sweep' (ignored update).
Data split into training (915 samples), validation (114 samples), and testing (114 samples) sets.
Number of classes: 6
Feature data normalized using z-score normalization.
Training:   0%|                                                                                                                                                                 | 0/1000 [00:00<?, ?epoch/s]
Traceback (most recent call last):
  File "/home/autrio/college-linx/SMAI/smai-m24-assignments-Autrio/assignments/3/2/2/3.py", line 101, in run
    model.train(epochs=params["epoch"])
  File "/home/autrio/college-linx/SMAI/smai-m24-assignments-Autrio/models/MLP/MLP2.py", line 436, in train
    train_loss, train_acc = self.train_step(train_loader)
  File "/home/autrio/college-linx/SMAI/smai-m24-assignments-Autrio/models/MLP/MLP2.py", line 411, in train_step
    loss += self.loss_fn(y, y_pred)
TypeError: 'str' object is not callable
