2024-10-08 04:42:27 INFO Running runs: []
2024-10-08 04:42:27 INFO Agent received command: run
2024-10-08 04:42:27 INFO Agent starting run with config:
	activation: Relu
	batch_size: 590
	epoch: 500
	loss_fn: <models.MLP.MLP2.Loss.MSELoss object at 0x7dd352ee1660>
	lr: 0.0011604015086770086
	type: classification
2024-10-08 04:42:27 INFO About to run command: /usr/bin/env python train.py --activation=Relu --batch_size=590 --epoch=500 "--loss_fn=<models.MLP.MLP2.Loss.MSELoss object at 0x7dd352ee1660>" --lr=0.0011604015086770086 --type=classification
2024-10-08 04:42:32 INFO Running runs: ['obz5vduk']
2024-10-08 04:42:32 INFO Cleaning up finished run: obz5vduk
2024-10-08 04:42:33 INFO Agent received command: run
2024-10-08 04:42:33 INFO Agent starting run with config:
	activation: tanh
	batch_size: 138
	epoch: 884
	loss_fn: <models.MLP.MLP2.Loss.MSELoss object at 0x7949b881d660>
	lr: 0.004642999436756801
	type: classification
2024-10-08 04:42:33 INFO About to run command: /usr/bin/env python train.py --activation=tanh --batch_size=138 --epoch=884 "--loss_fn=<models.MLP.MLP2.Loss.MSELoss object at 0x7949b881d660>" --lr=0.004642999436756801 --type=classification
2024-10-08 04:42:38 INFO Running runs: ['ekudbcfl']
2024-10-08 04:42:38 INFO Cleaning up finished run: ekudbcfl
2024-10-08 04:42:39 INFO Agent received command: run
2024-10-08 04:42:39 INFO Agent starting run with config:
	activation: Softmax
	batch_size: 215
	epoch: 1656
	loss_fn: <models.MLP.MLP2.Loss.MSELoss object at 0x7dd352ee1660>
	lr: 0.003314267535279654
	type: classification
2024-10-08 04:42:39 INFO About to run command: /usr/bin/env python train.py --activation=Softmax --batch_size=215 --epoch=1656 "--loss_fn=<models.MLP.MLP2.Loss.MSELoss object at 0x7dd352ee1660>" --lr=0.003314267535279654 --type=classification
2024-10-08 04:42:44 INFO Running runs: ['m6a57g0f']
2024-10-08 04:42:44 ERROR Detected 3 failed runs in the first 60 seconds, shutting down.
2024-10-08 04:42:44 INFO To disable this check set WANDB_AGENT_DISABLE_FLAPPING=true
2024-10-08 04:47:44 ERROR Traceback (most recent call last):
  File "/home/autrio/.local/lib/python3.10/site-packages/wandb/apis/normalize.py", line 41, in wrapper
    return func(*args, **kwargs)
  File "/home/autrio/.local/lib/python3.10/site-packages/wandb/sdk/internal/internal_api.py", line 1077, in sweep
    raise ValueError(f"Sweep {entity}/{project}/{sweep} not found")
ValueError: Sweep autrio-das-international-institute-of-information-techno/SMAI-A3-NN/0mre2dry not found

During handling of the above exception, another exception occurred:

Traceback (most recent call last):
  File "/home/autrio/.local/lib/python3.10/site-packages/wandb/cli/cli.py", line 108, in wrapper
    return func(*args, **kwargs)
  File "/home/autrio/.local/lib/python3.10/site-packages/wandb/cli/cli.py", line 1846, in agent
    wandb_agent.agent(sweep_id, entity=entity, project=project, count=count)
  File "/home/autrio/.local/lib/python3.10/site-packages/wandb/wandb_agent.py", line 572, in agent
    return run_agent(
  File "/home/autrio/.local/lib/python3.10/site-packages/wandb/wandb_agent.py", line 530, in run_agent
    agent.run()
  File "/home/autrio/.local/lib/python3.10/site-packages/wandb/wandb_agent.py", line 192, in run
    sweep_obj = self._api.sweep(self._sweep_id, "{}")
  File "/home/autrio/.local/lib/python3.10/site-packages/wandb/apis/internal.py", line 130, in sweep
    return self.api.sweep(*args, **kwargs)
  File "/home/autrio/.local/lib/python3.10/site-packages/wandb/apis/normalize.py", line 87, in wrapper
    raise CommError(message, err).with_traceback(sys.exc_info()[2])
  File "/home/autrio/.local/lib/python3.10/site-packages/wandb/apis/normalize.py", line 41, in wrapper
    return func(*args, **kwargs)
  File "/home/autrio/.local/lib/python3.10/site-packages/wandb/sdk/internal/internal_api.py", line 1077, in sweep
    raise ValueError(f"Sweep {entity}/{project}/{sweep} not found")
wandb.errors.errors.CommError: Sweep autrio-das-international-institute-of-information-techno/SMAI-A3-NN/0mre2dry not found

2024-10-08 04:51:59 ERROR 400 response executing GraphQL.
2024-10-08 04:51:59 ERROR {"errors":[{"message":"Invalid sweep config: Sweep config must contain method section","path":["upsertSweep"]}],"data":{"upsertSweep":null}}
2024-10-08 04:51:59 ERROR Traceback (most recent call last):
  File "/home/autrio/.local/lib/python3.10/site-packages/wandb/sdk/lib/retry.py", line 131, in __call__
    result = self._call_fn(*args, **kwargs)
  File "/home/autrio/.local/lib/python3.10/site-packages/wandb/sdk/internal/internal_api.py", line 347, in execute
    return self.client.execute(*args, **kwargs)  # type: ignore
  File "/home/autrio/.local/lib/python3.10/site-packages/wandb/vendor/gql-0.2.0/wandb_gql/client.py", line 52, in execute
    result = self._get_result(document, *args, **kwargs)
  File "/home/autrio/.local/lib/python3.10/site-packages/wandb/vendor/gql-0.2.0/wandb_gql/client.py", line 60, in _get_result
    return self.transport.execute(document, *args, **kwargs)
  File "/home/autrio/.local/lib/python3.10/site-packages/wandb/sdk/lib/gql_request.py", line 59, in execute
    request.raise_for_status()
  File "/home/autrio/.local/lib/python3.10/site-packages/requests/models.py", line 1021, in raise_for_status
    raise HTTPError(http_error_msg, response=self)
requests.exceptions.HTTPError: 400 Client Error: Bad Request for url: https://api.wandb.ai/graphql

During handling of the above exception, another exception occurred:

Traceback (most recent call last):
  File "/home/autrio/.local/lib/python3.10/site-packages/wandb/cli/cli.py", line 108, in wrapper
    return func(*args, **kwargs)
  File "/home/autrio/.local/lib/python3.10/site-packages/wandb/cli/cli.py", line 1055, in sweep
    sweep_id, warnings = api.upsert_sweep(
  File "/home/autrio/.local/lib/python3.10/site-packages/wandb/apis/internal.py", line 133, in upsert_sweep
    return self.api.upsert_sweep(*args, **kwargs)
  File "/home/autrio/.local/lib/python3.10/site-packages/wandb/apis/normalize.py", line 73, in wrapper
    raise err
  File "/home/autrio/.local/lib/python3.10/site-packages/wandb/apis/normalize.py", line 41, in wrapper
    return func(*args, **kwargs)
  File "/home/autrio/.local/lib/python3.10/site-packages/wandb/sdk/internal/internal_api.py", line 3287, in upsert_sweep
    raise e
  File "/home/autrio/.local/lib/python3.10/site-packages/wandb/sdk/internal/internal_api.py", line 3281, in upsert_sweep
    response = self.gql(
  File "/home/autrio/.local/lib/python3.10/site-packages/wandb/sdk/internal/internal_api.py", line 319, in gql
    ret = self._retry_gql(
  File "/home/autrio/.local/lib/python3.10/site-packages/wandb/sdk/lib/retry.py", line 147, in __call__
    retry_timedelta_triggered = check_retry_fn(e)
  File "/home/autrio/.local/lib/python3.10/site-packages/wandb/util.py", line 881, in no_retry_4xx
    raise UsageError(body["errors"][0]["message"])
wandb.errors.errors.UsageError: Invalid sweep config: Sweep config must contain method section

2024-10-08 04:52:21 ERROR 400 response executing GraphQL.
2024-10-08 04:52:21 ERROR {"errors":[{"message":"Invalid sweep config: Sweep config must contain method section","path":["upsertSweep"]}],"data":{"upsertSweep":null}}
2024-10-08 04:52:21 ERROR Traceback (most recent call last):
  File "/home/autrio/.local/lib/python3.10/site-packages/wandb/sdk/lib/retry.py", line 131, in __call__
    result = self._call_fn(*args, **kwargs)
  File "/home/autrio/.local/lib/python3.10/site-packages/wandb/sdk/internal/internal_api.py", line 347, in execute
    return self.client.execute(*args, **kwargs)  # type: ignore
  File "/home/autrio/.local/lib/python3.10/site-packages/wandb/vendor/gql-0.2.0/wandb_gql/client.py", line 52, in execute
    result = self._get_result(document, *args, **kwargs)
  File "/home/autrio/.local/lib/python3.10/site-packages/wandb/vendor/gql-0.2.0/wandb_gql/client.py", line 60, in _get_result
    return self.transport.execute(document, *args, **kwargs)
  File "/home/autrio/.local/lib/python3.10/site-packages/wandb/sdk/lib/gql_request.py", line 59, in execute
    request.raise_for_status()
  File "/home/autrio/.local/lib/python3.10/site-packages/requests/models.py", line 1021, in raise_for_status
    raise HTTPError(http_error_msg, response=self)
requests.exceptions.HTTPError: 400 Client Error: Bad Request for url: https://api.wandb.ai/graphql

During handling of the above exception, another exception occurred:

Traceback (most recent call last):
  File "/home/autrio/.local/lib/python3.10/site-packages/wandb/cli/cli.py", line 108, in wrapper
    return func(*args, **kwargs)
  File "/home/autrio/.local/lib/python3.10/site-packages/wandb/cli/cli.py", line 1055, in sweep
    sweep_id, warnings = api.upsert_sweep(
  File "/home/autrio/.local/lib/python3.10/site-packages/wandb/apis/internal.py", line 133, in upsert_sweep
    return self.api.upsert_sweep(*args, **kwargs)
  File "/home/autrio/.local/lib/python3.10/site-packages/wandb/apis/normalize.py", line 73, in wrapper
    raise err
  File "/home/autrio/.local/lib/python3.10/site-packages/wandb/apis/normalize.py", line 41, in wrapper
    return func(*args, **kwargs)
  File "/home/autrio/.local/lib/python3.10/site-packages/wandb/sdk/internal/internal_api.py", line 3287, in upsert_sweep
    raise e
  File "/home/autrio/.local/lib/python3.10/site-packages/wandb/sdk/internal/internal_api.py", line 3281, in upsert_sweep
    response = self.gql(
  File "/home/autrio/.local/lib/python3.10/site-packages/wandb/sdk/internal/internal_api.py", line 319, in gql
    ret = self._retry_gql(
  File "/home/autrio/.local/lib/python3.10/site-packages/wandb/sdk/lib/retry.py", line 147, in __call__
    retry_timedelta_triggered = check_retry_fn(e)
  File "/home/autrio/.local/lib/python3.10/site-packages/wandb/util.py", line 881, in no_retry_4xx
    raise UsageError(body["errors"][0]["message"])
wandb.errors.errors.UsageError: Invalid sweep config: Sweep config must contain method section

2024-10-08 04:53:05 ERROR 400 response executing GraphQL.
2024-10-08 04:53:05 ERROR {"errors":[{"message":"Invalid sweep config: Sweep config must contain method section","path":["upsertSweep"]}],"data":{"upsertSweep":null}}
2024-10-08 04:53:05 ERROR Traceback (most recent call last):
  File "/home/autrio/.local/lib/python3.10/site-packages/wandb/sdk/lib/retry.py", line 131, in __call__
    result = self._call_fn(*args, **kwargs)
  File "/home/autrio/.local/lib/python3.10/site-packages/wandb/sdk/internal/internal_api.py", line 347, in execute
    return self.client.execute(*args, **kwargs)  # type: ignore
  File "/home/autrio/.local/lib/python3.10/site-packages/wandb/vendor/gql-0.2.0/wandb_gql/client.py", line 52, in execute
    result = self._get_result(document, *args, **kwargs)
  File "/home/autrio/.local/lib/python3.10/site-packages/wandb/vendor/gql-0.2.0/wandb_gql/client.py", line 60, in _get_result
    return self.transport.execute(document, *args, **kwargs)
  File "/home/autrio/.local/lib/python3.10/site-packages/wandb/sdk/lib/gql_request.py", line 59, in execute
    request.raise_for_status()
  File "/home/autrio/.local/lib/python3.10/site-packages/requests/models.py", line 1021, in raise_for_status
    raise HTTPError(http_error_msg, response=self)
requests.exceptions.HTTPError: 400 Client Error: Bad Request for url: https://api.wandb.ai/graphql

During handling of the above exception, another exception occurred:

Traceback (most recent call last):
  File "/home/autrio/.local/lib/python3.10/site-packages/wandb/cli/cli.py", line 108, in wrapper
    return func(*args, **kwargs)
  File "/home/autrio/.local/lib/python3.10/site-packages/wandb/cli/cli.py", line 1055, in sweep
    sweep_id, warnings = api.upsert_sweep(
  File "/home/autrio/.local/lib/python3.10/site-packages/wandb/apis/internal.py", line 133, in upsert_sweep
    return self.api.upsert_sweep(*args, **kwargs)
  File "/home/autrio/.local/lib/python3.10/site-packages/wandb/apis/normalize.py", line 73, in wrapper
    raise err
  File "/home/autrio/.local/lib/python3.10/site-packages/wandb/apis/normalize.py", line 41, in wrapper
    return func(*args, **kwargs)
  File "/home/autrio/.local/lib/python3.10/site-packages/wandb/sdk/internal/internal_api.py", line 3287, in upsert_sweep
    raise e
  File "/home/autrio/.local/lib/python3.10/site-packages/wandb/sdk/internal/internal_api.py", line 3281, in upsert_sweep
    response = self.gql(
  File "/home/autrio/.local/lib/python3.10/site-packages/wandb/sdk/internal/internal_api.py", line 319, in gql
    ret = self._retry_gql(
  File "/home/autrio/.local/lib/python3.10/site-packages/wandb/sdk/lib/retry.py", line 147, in __call__
    retry_timedelta_triggered = check_retry_fn(e)
  File "/home/autrio/.local/lib/python3.10/site-packages/wandb/util.py", line 881, in no_retry_4xx
    raise UsageError(body["errors"][0]["message"])
wandb.errors.errors.UsageError: Invalid sweep config: Sweep config must contain method section

2024-10-08 04:53:32 ERROR 400 response executing GraphQL.
2024-10-08 04:53:32 ERROR {"errors":[{"message":"Invalid sweep config: Bayesian search requires \"metric\" section","path":["upsertSweep"]}],"data":{"upsertSweep":null}}
2024-10-08 04:53:32 ERROR Traceback (most recent call last):
  File "/home/autrio/.local/lib/python3.10/site-packages/wandb/sdk/lib/retry.py", line 131, in __call__
    result = self._call_fn(*args, **kwargs)
  File "/home/autrio/.local/lib/python3.10/site-packages/wandb/sdk/internal/internal_api.py", line 347, in execute
    return self.client.execute(*args, **kwargs)  # type: ignore
  File "/home/autrio/.local/lib/python3.10/site-packages/wandb/vendor/gql-0.2.0/wandb_gql/client.py", line 52, in execute
    result = self._get_result(document, *args, **kwargs)
  File "/home/autrio/.local/lib/python3.10/site-packages/wandb/vendor/gql-0.2.0/wandb_gql/client.py", line 60, in _get_result
    return self.transport.execute(document, *args, **kwargs)
  File "/home/autrio/.local/lib/python3.10/site-packages/wandb/sdk/lib/gql_request.py", line 59, in execute
    request.raise_for_status()
  File "/home/autrio/.local/lib/python3.10/site-packages/requests/models.py", line 1021, in raise_for_status
    raise HTTPError(http_error_msg, response=self)
requests.exceptions.HTTPError: 400 Client Error: Bad Request for url: https://api.wandb.ai/graphql

During handling of the above exception, another exception occurred:

Traceback (most recent call last):
  File "/home/autrio/.local/lib/python3.10/site-packages/wandb/cli/cli.py", line 108, in wrapper
    return func(*args, **kwargs)
  File "/home/autrio/.local/lib/python3.10/site-packages/wandb/cli/cli.py", line 1055, in sweep
    sweep_id, warnings = api.upsert_sweep(
  File "/home/autrio/.local/lib/python3.10/site-packages/wandb/apis/internal.py", line 133, in upsert_sweep
    return self.api.upsert_sweep(*args, **kwargs)
  File "/home/autrio/.local/lib/python3.10/site-packages/wandb/apis/normalize.py", line 73, in wrapper
    raise err
  File "/home/autrio/.local/lib/python3.10/site-packages/wandb/apis/normalize.py", line 41, in wrapper
    return func(*args, **kwargs)
  File "/home/autrio/.local/lib/python3.10/site-packages/wandb/sdk/internal/internal_api.py", line 3287, in upsert_sweep
    raise e
  File "/home/autrio/.local/lib/python3.10/site-packages/wandb/sdk/internal/internal_api.py", line 3281, in upsert_sweep
    response = self.gql(
  File "/home/autrio/.local/lib/python3.10/site-packages/wandb/sdk/internal/internal_api.py", line 319, in gql
    ret = self._retry_gql(
  File "/home/autrio/.local/lib/python3.10/site-packages/wandb/sdk/lib/retry.py", line 147, in __call__
    retry_timedelta_triggered = check_retry_fn(e)
  File "/home/autrio/.local/lib/python3.10/site-packages/wandb/util.py", line 881, in no_retry_4xx
    raise UsageError(body["errors"][0]["message"])
wandb.errors.errors.UsageError: Invalid sweep config: Bayesian search requires "metric" section

2024-10-08 04:57:29 INFO Running runs: []
2024-10-08 04:57:29 INFO Agent received command: run
2024-10-08 04:57:29 INFO Agent starting run with config:
	activation: Tanh
	batch_size: 256
	epochs: 100
	loss_fn: MSELoss
	lr: 0.0001
	optimizer: SGD
	type: classification
2024-10-08 04:57:29 INFO About to run command: /usr/bin/env python  --activation=Tanh --batch_size=256 --epochs=100 --loss_fn=MSELoss --lr=0.0001 --optimizer=SGD --type=classification
2024-10-08 04:57:34 INFO Running runs: ['o0bi0i5o']
2024-10-08 04:57:34 INFO Cleaning up finished run: o0bi0i5o
2024-10-08 04:57:35 INFO Agent received command: run
2024-10-08 04:57:35 INFO Agent starting run with config:
	activation: Sigmoid
	batch_size: 128
	epochs: 100
	loss_fn: BCELoss
	lr: 0.01
	optimizer: SGD
	type: classification
2024-10-08 04:57:35 INFO About to run command: /usr/bin/env python  --activation=Sigmoid --batch_size=128 --epochs=100 --loss_fn=BCELoss --lr=0.01 --optimizer=SGD --type=classification
2024-10-08 04:57:40 INFO Running runs: ['12fw5sz9']
2024-10-08 04:57:40 INFO Cleaning up finished run: 12fw5sz9
2024-10-08 04:57:41 INFO Agent received command: run
2024-10-08 04:57:41 INFO Agent starting run with config:
	activation: ReLU
	batch_size: 128
	epochs: 100
	loss_fn: MSELoss
	lr: 0.0001
	optimizer: batch
	type: classification
2024-10-08 04:57:41 INFO About to run command: /usr/bin/env python  --activation=ReLU --batch_size=128 --epochs=100 --loss_fn=MSELoss --lr=0.0001 --optimizer=batch --type=classification
2024-10-08 04:57:46 INFO Running runs: ['nbugt0m5']
2024-10-08 04:57:46 ERROR Detected 3 failed runs in the first 60 seconds, shutting down.
2024-10-08 04:57:46 INFO To disable this check set WANDB_AGENT_DISABLE_FLAPPING=true
2024-10-08 05:00:50 ERROR 400 response executing GraphQL.
2024-10-08 05:00:50 ERROR {"errors":[{"message":"name required for project query","path":["project"]}],"data":{"project":null}}
2024-10-08 05:00:50 ERROR Traceback (most recent call last):
  File "/home/autrio/.local/lib/python3.10/site-packages/wandb/apis/normalize.py", line 41, in wrapper
    return func(*args, **kwargs)
  File "/home/autrio/.local/lib/python3.10/site-packages/wandb/sdk/internal/internal_api.py", line 1067, in sweep
    response = self.gql(
  File "/home/autrio/.local/lib/python3.10/site-packages/wandb/sdk/internal/internal_api.py", line 319, in gql
    ret = self._retry_gql(
  File "/home/autrio/.local/lib/python3.10/site-packages/wandb/sdk/lib/retry.py", line 131, in __call__
    result = self._call_fn(*args, **kwargs)
  File "/home/autrio/.local/lib/python3.10/site-packages/wandb/sdk/internal/internal_api.py", line 347, in execute
    return self.client.execute(*args, **kwargs)  # type: ignore
  File "/home/autrio/.local/lib/python3.10/site-packages/wandb/vendor/gql-0.2.0/wandb_gql/client.py", line 52, in execute
    result = self._get_result(document, *args, **kwargs)
  File "/home/autrio/.local/lib/python3.10/site-packages/wandb/vendor/gql-0.2.0/wandb_gql/client.py", line 60, in _get_result
    return self.transport.execute(document, *args, **kwargs)
  File "/home/autrio/.local/lib/python3.10/site-packages/wandb/sdk/lib/gql_request.py", line 59, in execute
    request.raise_for_status()
  File "/home/autrio/.local/lib/python3.10/site-packages/requests/models.py", line 1021, in raise_for_status
    raise HTTPError(http_error_msg, response=self)
requests.exceptions.HTTPError: 400 Client Error: Bad Request for url: https://api.wandb.ai/graphql

During handling of the above exception, another exception occurred:

Traceback (most recent call last):
  File "/home/autrio/.local/lib/python3.10/site-packages/wandb/cli/cli.py", line 108, in wrapper
    return func(*args, **kwargs)
  File "/home/autrio/.local/lib/python3.10/site-packages/wandb/cli/cli.py", line 1846, in agent
    wandb_agent.agent(sweep_id, entity=entity, project=project, count=count)
  File "/home/autrio/.local/lib/python3.10/site-packages/wandb/wandb_agent.py", line 572, in agent
    return run_agent(
  File "/home/autrio/.local/lib/python3.10/site-packages/wandb/wandb_agent.py", line 530, in run_agent
    agent.run()
  File "/home/autrio/.local/lib/python3.10/site-packages/wandb/wandb_agent.py", line 192, in run
    sweep_obj = self._api.sweep(self._sweep_id, "{}")
  File "/home/autrio/.local/lib/python3.10/site-packages/wandb/apis/internal.py", line 130, in sweep
    return self.api.sweep(*args, **kwargs)
  File "/home/autrio/.local/lib/python3.10/site-packages/wandb/apis/normalize.py", line 51, in wrapper
    raise CommError(message, error)
wandb.errors.errors.CommError: name required for project query (Error 400: Bad Request)

2024-10-08 05:01:25 ERROR 400 response executing GraphQL.
2024-10-08 05:01:25 ERROR {"errors":[{"message":"name required for project query","path":["project"]}],"data":{"project":null}}
2024-10-08 05:01:25 ERROR Traceback (most recent call last):
  File "/home/autrio/.local/lib/python3.10/site-packages/wandb/apis/normalize.py", line 41, in wrapper
    return func(*args, **kwargs)
  File "/home/autrio/.local/lib/python3.10/site-packages/wandb/sdk/internal/internal_api.py", line 1067, in sweep
    response = self.gql(
  File "/home/autrio/.local/lib/python3.10/site-packages/wandb/sdk/internal/internal_api.py", line 319, in gql
    ret = self._retry_gql(
  File "/home/autrio/.local/lib/python3.10/site-packages/wandb/sdk/lib/retry.py", line 131, in __call__
    result = self._call_fn(*args, **kwargs)
  File "/home/autrio/.local/lib/python3.10/site-packages/wandb/sdk/internal/internal_api.py", line 347, in execute
    return self.client.execute(*args, **kwargs)  # type: ignore
  File "/home/autrio/.local/lib/python3.10/site-packages/wandb/vendor/gql-0.2.0/wandb_gql/client.py", line 52, in execute
    result = self._get_result(document, *args, **kwargs)
  File "/home/autrio/.local/lib/python3.10/site-packages/wandb/vendor/gql-0.2.0/wandb_gql/client.py", line 60, in _get_result
    return self.transport.execute(document, *args, **kwargs)
  File "/home/autrio/.local/lib/python3.10/site-packages/wandb/sdk/lib/gql_request.py", line 59, in execute
    request.raise_for_status()
  File "/home/autrio/.local/lib/python3.10/site-packages/requests/models.py", line 1021, in raise_for_status
    raise HTTPError(http_error_msg, response=self)
requests.exceptions.HTTPError: 400 Client Error: Bad Request for url: https://api.wandb.ai/graphql

During handling of the above exception, another exception occurred:

Traceback (most recent call last):
  File "/home/autrio/.local/lib/python3.10/site-packages/wandb/cli/cli.py", line 108, in wrapper
    return func(*args, **kwargs)
  File "/home/autrio/.local/lib/python3.10/site-packages/wandb/cli/cli.py", line 1846, in agent
    wandb_agent.agent(sweep_id, entity=entity, project=project, count=count)
  File "/home/autrio/.local/lib/python3.10/site-packages/wandb/wandb_agent.py", line 572, in agent
    return run_agent(
  File "/home/autrio/.local/lib/python3.10/site-packages/wandb/wandb_agent.py", line 530, in run_agent
    agent.run()
  File "/home/autrio/.local/lib/python3.10/site-packages/wandb/wandb_agent.py", line 192, in run
    sweep_obj = self._api.sweep(self._sweep_id, "{}")
  File "/home/autrio/.local/lib/python3.10/site-packages/wandb/apis/internal.py", line 130, in sweep
    return self.api.sweep(*args, **kwargs)
  File "/home/autrio/.local/lib/python3.10/site-packages/wandb/apis/normalize.py", line 51, in wrapper
    raise CommError(message, error)
wandb.errors.errors.CommError: name required for project query (Error 400: Bad Request)

2024-10-08 05:02:00 ERROR 400 response executing GraphQL.
2024-10-08 05:02:00 ERROR {"errors":[{"message":"name required for project query","path":["project"]}],"data":{"project":null}}
2024-10-08 05:02:00 ERROR Traceback (most recent call last):
  File "/home/autrio/.local/lib/python3.10/site-packages/wandb/apis/normalize.py", line 41, in wrapper
    return func(*args, **kwargs)
  File "/home/autrio/.local/lib/python3.10/site-packages/wandb/sdk/internal/internal_api.py", line 1067, in sweep
    response = self.gql(
  File "/home/autrio/.local/lib/python3.10/site-packages/wandb/sdk/internal/internal_api.py", line 319, in gql
    ret = self._retry_gql(
  File "/home/autrio/.local/lib/python3.10/site-packages/wandb/sdk/lib/retry.py", line 131, in __call__
    result = self._call_fn(*args, **kwargs)
  File "/home/autrio/.local/lib/python3.10/site-packages/wandb/sdk/internal/internal_api.py", line 347, in execute
    return self.client.execute(*args, **kwargs)  # type: ignore
  File "/home/autrio/.local/lib/python3.10/site-packages/wandb/vendor/gql-0.2.0/wandb_gql/client.py", line 52, in execute
    result = self._get_result(document, *args, **kwargs)
  File "/home/autrio/.local/lib/python3.10/site-packages/wandb/vendor/gql-0.2.0/wandb_gql/client.py", line 60, in _get_result
    return self.transport.execute(document, *args, **kwargs)
  File "/home/autrio/.local/lib/python3.10/site-packages/wandb/sdk/lib/gql_request.py", line 59, in execute
    request.raise_for_status()
  File "/home/autrio/.local/lib/python3.10/site-packages/requests/models.py", line 1021, in raise_for_status
    raise HTTPError(http_error_msg, response=self)
requests.exceptions.HTTPError: 400 Client Error: Bad Request for url: https://api.wandb.ai/graphql

During handling of the above exception, another exception occurred:

Traceback (most recent call last):
  File "/home/autrio/.local/lib/python3.10/site-packages/wandb/cli/cli.py", line 108, in wrapper
    return func(*args, **kwargs)
  File "/home/autrio/.local/lib/python3.10/site-packages/wandb/cli/cli.py", line 1846, in agent
    wandb_agent.agent(sweep_id, entity=entity, project=project, count=count)
  File "/home/autrio/.local/lib/python3.10/site-packages/wandb/wandb_agent.py", line 572, in agent
    return run_agent(
  File "/home/autrio/.local/lib/python3.10/site-packages/wandb/wandb_agent.py", line 530, in run_agent
    agent.run()
  File "/home/autrio/.local/lib/python3.10/site-packages/wandb/wandb_agent.py", line 192, in run
    sweep_obj = self._api.sweep(self._sweep_id, "{}")
  File "/home/autrio/.local/lib/python3.10/site-packages/wandb/apis/internal.py", line 130, in sweep
    return self.api.sweep(*args, **kwargs)
  File "/home/autrio/.local/lib/python3.10/site-packages/wandb/apis/normalize.py", line 51, in wrapper
    raise CommError(message, error)
wandb.errors.errors.CommError: name required for project query (Error 400: Bad Request)

