2024-10-09 22:15:37,155 INFO    Thread-5 (_run_job):510491 [wandb_setup.py:_flush():79] Current SDK version is 0.18.3
2024-10-09 22:15:37,155 INFO    Thread-5 (_run_job):510491 [wandb_setup.py:_flush():79] Configure stats pid to 510491
2024-10-09 22:15:37,155 INFO    Thread-5 (_run_job):510491 [wandb_setup.py:_flush():79] Loading settings from /home/autrio/.config/wandb/settings
2024-10-09 22:15:37,155 INFO    Thread-5 (_run_job):510491 [wandb_setup.py:_flush():79] Loading settings from /home/autrio/college-linx/SMAI/smai-m24-assignments-Autrio/wandb/settings
2024-10-09 22:15:37,155 INFO    Thread-5 (_run_job):510491 [wandb_setup.py:_flush():79] Loading settings from environment variables: {'project': 'SMAI-A3-MLP', 'entity': 'autrio-das-international-institute-of-information-techno', 'root_dir': '/home/autrio/college-linx/SMAI/smai-m24-assignments-Autrio', 'run_id': 'pdp8hfqv', 'sweep_param_path': '/home/autrio/college-linx/SMAI/smai-m24-assignments-Autrio/wandb/sweep-jplbuq81/config-pdp8hfqv.yaml', 'sweep_id': 'jplbuq81'}
2024-10-09 22:15:37,155 INFO    Thread-5 (_run_job):510491 [wandb_setup.py:_flush():79] Applying setup settings: {'mode': None, '_disable_service': None}
2024-10-09 22:15:37,155 WARNING Thread-5 (_run_job):510491 [wandb_setup.py:_flush():79] Could not find program at -m assignments.3.2.2.3
2024-10-09 22:15:37,155 INFO    Thread-5 (_run_job):510491 [wandb_setup.py:_flush():79] Inferring run settings from compute environment: {'program_relpath': None, 'program': '-m assignments.3.2.2.3'}
2024-10-09 22:15:37,155 INFO    Thread-5 (_run_job):510491 [wandb_setup.py:_flush():79] Applying login settings: {}
2024-10-09 22:15:37,155 INFO    Thread-5 (_run_job):510491 [wandb_init.py:_log_setup():532] Logging user logs to /home/autrio/college-linx/SMAI/smai-m24-assignments-Autrio/wandb/run-20241009_221537-pdp8hfqv/logs/debug.log
2024-10-09 22:15:37,155 INFO    Thread-5 (_run_job):510491 [wandb_init.py:_log_setup():533] Logging internal logs to /home/autrio/college-linx/SMAI/smai-m24-assignments-Autrio/wandb/run-20241009_221537-pdp8hfqv/logs/debug-internal.log
2024-10-09 22:15:37,155 INFO    Thread-5 (_run_job):510491 [wandb_init.py:init():617] calling init triggers
2024-10-09 22:15:37,155 INFO    Thread-5 (_run_job):510491 [wandb_init.py:init():624] wandb.init called with sweep_config: {'activations': 'Linear', 'batch_size': 32, 'epoch': 4000, 'loss_fn': 'BCELoss', 'lr': 0.03021580590166869, 'model_architecture': 'arch3', 'type': 'classification'}
config: {'lr': 0.001, 'batch_size': 256, 'epoch': 1000, 'optimizer': 'mini-batch', 'loss_fn': <models.MLP.MLP2.loss.MSELoss object at 0x732ff766fca0>, 'activation': <models.MLP.MLP2.activations.Tanh object at 0x732ff76fc7f0>, 'type': 'classification', 'logger': <module 'wandb' from '/home/autrio/.local/lib/python3.10/site-packages/wandb/__init__.py'>}
2024-10-09 22:15:37,155 INFO    Thread-5 (_run_job):510491 [wandb_init.py:init():667] starting backend
2024-10-09 22:15:37,155 INFO    Thread-5 (_run_job):510491 [wandb_init.py:init():671] sending inform_init request
2024-10-09 22:15:37,158 INFO    Thread-5 (_run_job):510491 [backend.py:_multiprocessing_setup():104] multiprocessing start_methods=fork,spawn,forkserver, using: spawn
2024-10-09 22:15:37,158 INFO    Thread-5 (_run_job):510491 [wandb_init.py:init():684] backend started and connected
2024-10-09 22:15:37,162 INFO    Thread-5 (_run_job):510491 [wandb_run.py:_config_callback():1394] config_cb None None {'activations': 'Linear', 'batch_size': 32, 'epoch': 4000, 'loss_fn': 'BCELoss', 'lr': 0.03021580590166869, 'model_architecture': 'arch3', 'type': 'classification'}
2024-10-09 22:15:37,163 INFO    Thread-5 (_run_job):510491 [wandb_init.py:init():779] updated telemetry
2024-10-09 22:15:37,166 INFO    Thread-5 (_run_job):510491 [wandb_init.py:init():812] communicating run to backend with 90.0 second timeout
2024-10-09 22:15:37,166 ERROR   Thread-5 (_run_job):510491 [wandb_init.py:init():1262] error in wandb.init()
Traceback (most recent call last):
  File "/home/autrio/.local/lib/python3.10/site-packages/wandb/sdk/wandb_init.py", line 1252, in init
    return wi.init()
  File "/home/autrio/.local/lib/python3.10/site-packages/wandb/sdk/wandb_init.py", line 814, in init
    run_init_handle = backend.interface.deliver_run(run)
  File "/home/autrio/.local/lib/python3.10/site-packages/wandb/sdk/interface/interface.py", line 843, in deliver_run
    run_record = self._make_run(run)
  File "/home/autrio/.local/lib/python3.10/site-packages/wandb/sdk/interface/interface.py", line 157, in _make_run
    self._make_config(data=config_dict, obj=proto_run.config)
  File "/home/autrio/.local/lib/python3.10/site-packages/wandb/sdk/interface/interface.py", line 139, in _make_config
    update.value_json = json_dumps_safer(json_friendly(v)[0])
  File "/home/autrio/.local/lib/python3.10/site-packages/wandb/util.py", line 831, in json_dumps_safer
    return dumps(obj, cls=WandBJSONEncoder, **kwargs)
  File "/usr/lib/python3.10/json/__init__.py", line 238, in dumps
    **kw).encode(obj)
  File "/usr/lib/python3.10/json/encoder.py", line 199, in encode
    chunks = self.iterencode(o, _one_shot=True)
  File "/usr/lib/python3.10/json/encoder.py", line 257, in iterencode
    return _iterencode(o, 0)
  File "/home/autrio/.local/lib/python3.10/site-packages/wandb/util.py", line 782, in default
    return json.JSONEncoder.default(self, obj)
  File "/usr/lib/python3.10/json/encoder.py", line 179, in default
    raise TypeError(f'Object of type {o.__class__.__name__} '
TypeError: Object of type module is not JSON serializable
2024-10-09 22:15:37,299 ERROR   MainThread:510491 [pyagent.py:_run_jobs_from_queue():234] Run pdp8hfqv errored:
Traceback (most recent call last):
  File "/home/autrio/.local/lib/python3.10/site-packages/wandb/agents/pyagent.py", line 306, in _run_job
    self._function()
  File "/home/autrio/college-linx/SMAI/smai-m24-assignments-Autrio/assignments/3/2/2/3.py", line 62, in run
    with wandb.init(config=params):
  File "/home/autrio/.local/lib/python3.10/site-packages/wandb/sdk/wandb_init.py", line 1266, in init
    wandb._sentry.reraise(e)
  File "/home/autrio/.local/lib/python3.10/site-packages/wandb/analytics/sentry.py", line 155, in reraise
    raise exc.with_traceback(sys.exc_info()[2])
  File "/home/autrio/.local/lib/python3.10/site-packages/wandb/sdk/wandb_init.py", line 1252, in init
    return wi.init()
  File "/home/autrio/.local/lib/python3.10/site-packages/wandb/sdk/wandb_init.py", line 814, in init
    run_init_handle = backend.interface.deliver_run(run)
  File "/home/autrio/.local/lib/python3.10/site-packages/wandb/sdk/interface/interface.py", line 843, in deliver_run
    run_record = self._make_run(run)
  File "/home/autrio/.local/lib/python3.10/site-packages/wandb/sdk/interface/interface.py", line 157, in _make_run
    self._make_config(data=config_dict, obj=proto_run.config)
  File "/home/autrio/.local/lib/python3.10/site-packages/wandb/sdk/interface/interface.py", line 139, in _make_config
    update.value_json = json_dumps_safer(json_friendly(v)[0])
  File "/home/autrio/.local/lib/python3.10/site-packages/wandb/util.py", line 831, in json_dumps_safer
    return dumps(obj, cls=WandBJSONEncoder, **kwargs)
  File "/usr/lib/python3.10/json/__init__.py", line 238, in dumps
    **kw).encode(obj)
  File "/usr/lib/python3.10/json/encoder.py", line 199, in encode
    chunks = self.iterencode(o, _one_shot=True)
  File "/usr/lib/python3.10/json/encoder.py", line 257, in iterencode
    return _iterencode(o, 0)
  File "/home/autrio/.local/lib/python3.10/site-packages/wandb/util.py", line 782, in default
    return json.JSONEncoder.default(self, obj)
  File "/usr/lib/python3.10/json/encoder.py", line 179, in default
    raise TypeError(f'Object of type {o.__class__.__name__} '
TypeError: Object of type module is not JSON serializable

2024-10-09 22:15:40,988 WARNING MsgRouterThr:510491 [router.py:message_loop():77] message_loop has been closed
2024-10-09 22:15:42,604 INFO    Thread-8 (_run_job):510491 [wandb_setup.py:_flush():79] Current SDK version is 0.18.3
2024-10-09 22:15:42,604 INFO    Thread-8 (_run_job):510491 [wandb_setup.py:_flush():79] Configure stats pid to 510491
2024-10-09 22:15:42,604 INFO    Thread-8 (_run_job):510491 [wandb_setup.py:_flush():79] Loading settings from /home/autrio/.config/wandb/settings
2024-10-09 22:15:42,605 INFO    Thread-8 (_run_job):510491 [wandb_setup.py:_flush():79] Loading settings from /home/autrio/college-linx/SMAI/smai-m24-assignments-Autrio/wandb/settings
2024-10-09 22:15:42,605 INFO    Thread-8 (_run_job):510491 [wandb_setup.py:_flush():79] Loading settings from environment variables: {'project': 'SMAI-A3-MLP', 'entity': 'autrio-das-international-institute-of-information-techno', 'root_dir': '/home/autrio/college-linx/SMAI/smai-m24-assignments-Autrio', 'run_id': 'ywhwxozw', 'sweep_param_path': '/home/autrio/college-linx/SMAI/smai-m24-assignments-Autrio/wandb/sweep-jplbuq81/config-ywhwxozw.yaml', 'sweep_id': 'jplbuq81'}
2024-10-09 22:15:42,605 INFO    Thread-8 (_run_job):510491 [wandb_setup.py:_flush():79] Applying setup settings: {'mode': None, '_disable_service': None}
2024-10-09 22:15:42,605 WARNING Thread-8 (_run_job):510491 [wandb_setup.py:_flush():79] Could not find program at -m assignments.3.2.2.3
2024-10-09 22:15:42,605 INFO    Thread-8 (_run_job):510491 [wandb_setup.py:_flush():79] Inferring run settings from compute environment: {'program_relpath': None, 'program': '-m assignments.3.2.2.3'}
2024-10-09 22:15:42,605 INFO    Thread-8 (_run_job):510491 [wandb_setup.py:_flush():79] Applying login settings: {}
2024-10-09 22:15:42,605 INFO    Thread-8 (_run_job):510491 [wandb_init.py:_log_setup():532] Logging user logs to /home/autrio/college-linx/SMAI/smai-m24-assignments-Autrio/wandb/run-20241009_221542-ywhwxozw/logs/debug.log
2024-10-09 22:15:42,605 INFO    Thread-8 (_run_job):510491 [wandb_init.py:_log_setup():533] Logging internal logs to /home/autrio/college-linx/SMAI/smai-m24-assignments-Autrio/wandb/run-20241009_221542-ywhwxozw/logs/debug-internal.log
2024-10-09 22:15:42,605 INFO    Thread-8 (_run_job):510491 [wandb_init.py:init():617] calling init triggers
2024-10-09 22:15:42,605 INFO    Thread-8 (_run_job):510491 [wandb_init.py:init():624] wandb.init called with sweep_config: {'activations': 'Softmax', 'batch_size': 256, 'epoch': 4000, 'loss_fn': 'MSELoss', 'lr': 0.0642814206911225, 'model_architecture': 'arch3', 'type': 'classification'}
config: {'lr': 0.001, 'batch_size': 256, 'epoch': 1000, 'optimizer': 'mini-batch', 'loss_fn': <models.MLP.MLP2.loss.MSELoss object at 0x732ff6d24580>, 'activation': <models.MLP.MLP2.activations.Tanh object at 0x732ff76fd600>, 'type': 'classification', 'logger': <module 'wandb' from '/home/autrio/.local/lib/python3.10/site-packages/wandb/__init__.py'>}
2024-10-09 22:15:42,605 INFO    Thread-8 (_run_job):510491 [wandb_init.py:init():667] starting backend
2024-10-09 22:15:42,605 INFO    Thread-8 (_run_job):510491 [wandb_init.py:init():671] sending inform_init request
2024-10-09 22:15:42,608 INFO    Thread-8 (_run_job):510491 [backend.py:_multiprocessing_setup():104] multiprocessing start_methods=fork,spawn,forkserver, using: spawn
2024-10-09 22:15:42,608 INFO    Thread-8 (_run_job):510491 [wandb_init.py:init():684] backend started and connected
2024-10-09 22:15:42,612 INFO    Thread-8 (_run_job):510491 [wandb_run.py:_config_callback():1394] config_cb None None {'activations': 'Softmax', 'batch_size': 256, 'epoch': 4000, 'loss_fn': 'MSELoss', 'lr': 0.0642814206911225, 'model_architecture': 'arch3', 'type': 'classification'}
2024-10-09 22:15:42,613 INFO    Thread-8 (_run_job):510491 [wandb_init.py:init():779] updated telemetry
2024-10-09 22:15:42,616 INFO    Thread-8 (_run_job):510491 [wandb_init.py:init():812] communicating run to backend with 90.0 second timeout
2024-10-09 22:15:42,616 ERROR   Thread-8 (_run_job):510491 [wandb_init.py:init():1262] error in wandb.init()
Traceback (most recent call last):
  File "/home/autrio/.local/lib/python3.10/site-packages/wandb/sdk/wandb_init.py", line 1252, in init
    return wi.init()
  File "/home/autrio/.local/lib/python3.10/site-packages/wandb/sdk/wandb_init.py", line 814, in init
    run_init_handle = backend.interface.deliver_run(run)
  File "/home/autrio/.local/lib/python3.10/site-packages/wandb/sdk/interface/interface.py", line 843, in deliver_run
    run_record = self._make_run(run)
  File "/home/autrio/.local/lib/python3.10/site-packages/wandb/sdk/interface/interface.py", line 157, in _make_run
    self._make_config(data=config_dict, obj=proto_run.config)
  File "/home/autrio/.local/lib/python3.10/site-packages/wandb/sdk/interface/interface.py", line 139, in _make_config
    update.value_json = json_dumps_safer(json_friendly(v)[0])
  File "/home/autrio/.local/lib/python3.10/site-packages/wandb/util.py", line 831, in json_dumps_safer
    return dumps(obj, cls=WandBJSONEncoder, **kwargs)
  File "/usr/lib/python3.10/json/__init__.py", line 238, in dumps
    **kw).encode(obj)
  File "/usr/lib/python3.10/json/encoder.py", line 199, in encode
    chunks = self.iterencode(o, _one_shot=True)
  File "/usr/lib/python3.10/json/encoder.py", line 257, in iterencode
    return _iterencode(o, 0)
  File "/home/autrio/.local/lib/python3.10/site-packages/wandb/util.py", line 782, in default
    return json.JSONEncoder.default(self, obj)
  File "/usr/lib/python3.10/json/encoder.py", line 179, in default
    raise TypeError(f'Object of type {o.__class__.__name__} '
TypeError: Object of type module is not JSON serializable
2024-10-09 22:15:42,750 ERROR   MainThread:510491 [pyagent.py:_run_jobs_from_queue():234] Run ywhwxozw errored:
Traceback (most recent call last):
  File "/home/autrio/.local/lib/python3.10/site-packages/wandb/agents/pyagent.py", line 306, in _run_job
    self._function()
  File "/home/autrio/college-linx/SMAI/smai-m24-assignments-Autrio/assignments/3/2/2/3.py", line 62, in run
    with wandb.init(config=params):
  File "/home/autrio/.local/lib/python3.10/site-packages/wandb/sdk/wandb_init.py", line 1266, in init
    wandb._sentry.reraise(e)
  File "/home/autrio/.local/lib/python3.10/site-packages/wandb/analytics/sentry.py", line 155, in reraise
    raise exc.with_traceback(sys.exc_info()[2])
  File "/home/autrio/.local/lib/python3.10/site-packages/wandb/sdk/wandb_init.py", line 1252, in init
    return wi.init()
  File "/home/autrio/.local/lib/python3.10/site-packages/wandb/sdk/wandb_init.py", line 814, in init
    run_init_handle = backend.interface.deliver_run(run)
  File "/home/autrio/.local/lib/python3.10/site-packages/wandb/sdk/interface/interface.py", line 843, in deliver_run
    run_record = self._make_run(run)
  File "/home/autrio/.local/lib/python3.10/site-packages/wandb/sdk/interface/interface.py", line 157, in _make_run
    self._make_config(data=config_dict, obj=proto_run.config)
  File "/home/autrio/.local/lib/python3.10/site-packages/wandb/sdk/interface/interface.py", line 139, in _make_config
    update.value_json = json_dumps_safer(json_friendly(v)[0])
  File "/home/autrio/.local/lib/python3.10/site-packages/wandb/util.py", line 831, in json_dumps_safer
    return dumps(obj, cls=WandBJSONEncoder, **kwargs)
  File "/usr/lib/python3.10/json/__init__.py", line 238, in dumps
    **kw).encode(obj)
  File "/usr/lib/python3.10/json/encoder.py", line 199, in encode
    chunks = self.iterencode(o, _one_shot=True)
  File "/usr/lib/python3.10/json/encoder.py", line 257, in iterencode
    return _iterencode(o, 0)
  File "/home/autrio/.local/lib/python3.10/site-packages/wandb/util.py", line 782, in default
    return json.JSONEncoder.default(self, obj)
  File "/usr/lib/python3.10/json/encoder.py", line 179, in default
    raise TypeError(f'Object of type {o.__class__.__name__} '
TypeError: Object of type module is not JSON serializable

2024-10-09 22:15:42,750 ERROR   MainThread:510491 [pyagent.py:_run_jobs_from_queue():245] Detected 3 failed runs in the first 60 seconds, killing sweep.
2024-10-09 22:15:42,751 WARNING MsgRouterThr:510491 [router.py:message_loop():77] message_loop has been closed
